#VRML_SIM R2025a utf8

EXTERNPROTO "https://raw.githubusercontent.com/cyberbotics/webots/R2025a/projects/objects/backgrounds/protos/TexturedBackground.proto"
EXTERNPROTO "https://raw.githubusercontent.com/cyberbotics/webots/R2025a/projects/objects/backgrounds/protos/TexturedBackgroundLight.proto"
EXTERNPROTO "https://raw.githubusercontent.com/cyberbotics/webots/R2025a/projects/objects/floors/protos/RectangleArena.proto"

WorldInfo {
  info [
    "Thanks to Mehdi Ghanavati, Shahid Chamran University"
    "Modified to 4 Wheels & Octagon Base"
  ]
  title "Omni-wheels 4-Axis"
  basicTimeStep 8
}
Viewpoint {
  orientation -0.13171347712082856 -0.1044621623817099 0.9857683381886833 4.384301823563855
  position 0.9568327219515322 2.4094106275451908 0.9411015343908566
}
TexturedBackground {
}
TexturedBackgroundLight {
}
RectangleArena {
  floorSize 5 5
}
DEF OMNI_WHEELS Robot {
  translation 0.17526794527882164 -0.4586560699810617 0.05941107519086716
  rotation 0.0006231985988844388 -0.001868632975094045 -0.9999980599152734 -2.8575820240471113
  children [
    DEF SOLID1 Solid {
      translation -0.14 0 0
      children [
        DEF WHEEL1 HingeJoint {
          jointParameters HingeJointParameters {
            position 85.89008468547705
            axis -1 0 0
            anchor -0.1 0 0
          }
          device [
            RotationalMotor {
              name "wheel1"
            }
          ]
          endPoint Solid {
            translation -0.10000150154995513 -1.4432581228420003e-05 5.468754041624479e-06
            rotation 0.9999999998334366 1.6968062939662858e-05 6.723941826789997e-06 2.0745094567650413
            children [
              DEF sr1 HingeJoint {
                jointParameters HingeJointParameters {
                  position 28.209075021712067
                  axis 0 1 0
                  anchor -0.02 0 0.05
                }
                endPoint Solid {
                  translation -0.02 0 0.05
                  rotation 0 1 0 3.0763337929937213
                  children [
                    DEF r1 Pose {
                      rotation -1 0 0 1.5708
                      children [
                        DEF SMALL_WHEEL_SHAPE Shape {
                          appearance PBRAppearance {
                            baseColor 1 0.752941 0.796078
                            roughness 1
                            metalness 0
                          }
                          geometry Cylinder {
                            height 0.02
                            radius 0.01
                          }
                        }
                      ]
                    }
                  ]
                  name "sr1"
                  boundingObject USE r1
                  physics Physics {
                    density -1
                    mass 0.1
                  }
                  linearVelocity -0.006389519927742856 -0.28072381166867183 0.3085017187565666
                  angularVelocity 7.589213404077407 -1.766472894048848 -1.008853223224312
                }
              }
              DEF sr2 HingeJoint {
                jointParameters HingeJointParameters {
                  position -12.412150062839338
                  axis 0 -0.707107 0.707107
                  anchor -0.02 0.03535 0.03535
                }
                endPoint Solid {
                  translation -0.02 0.03535 0.03535
                  rotation 0 -0.7071067811865476 0.7071067811865476 0.15422055151983577
                  children [
                    DEF r2 Pose {
                      rotation -1 0 0 2.27
                      children [
                        USE SMALL_WHEEL_SHAPE
                      ]
                    }
                  ]
                  name "sr2"
                  boundingObject USE r2
                  physics Physics {
                    density -1
                    mass 0.1
                  }
                  linearVelocity -0.08271058475143377 -0.5684614381823817 0.352465459667701
                  angularVelocity 7.237202340856017 -3.107691093411446 1.5235166425751958
                }
              }
              DEF sr3 HingeJoint {
                jointParameters HingeJointParameters {
                  position 59.54232215763651
                  axis 0 1 0
                  anchor -0.02 0 -0.05
                }
                endPoint Solid {
                  translation -0.02 0 -0.05
                  rotation 0 -1 0 3.2895309141593527
                  children [
                    DEF r3 Pose {
                      rotation -1 0 0 1.5708
                      children [
                        USE SMALL_WHEEL_SHAPE
                      ]
                    }
                  ]
                  name "sr3"
                  boundingObject USE r3
                  physics Physics {
                    density -1
                    mass 0.1
                  }
                  linearVelocity -0.2814137880192555 -0.6231307263887609 -0.3651833019249437
                  angularVelocity 7.276981976478157 -2.8621180425258412 -2.9234884838223514
                }
              }
              DEF sr4 HingeJoint {
                jointParameters HingeJointParameters {
                  position -5.042260562800642
                  axis 0 -0.707107 0.707107
                  anchor -0.02 -0.03535 -0.03535
                }
                endPoint Solid {
                  translation -0.02 -0.03535 -0.03535
                  rotation 0 0.7071067811865475 -0.7071067811865475 5.042260562800642
                  children [
                    DEF r4 Pose {
                      rotation -1 0 0 2.27
                      children [
                        USE SMALL_WHEEL_SHAPE
                      ]
                    }
                  ]
                  name "sr4"
                  boundingObject USE r4
                  physics Physics {
                    density -1
                    mass 0.1
                  }
                  linearVelocity -0.20509279366090938 -0.3353919309177967 -0.4091302713989863
                  angularVelocity 6.764351818923241 -5.5346147307063776 11.720502165504985
                }
              }
              DEF sr5 HingeJoint {
                jointParameters HingeJointParameters {
                  position -2.131294828259337
                  axis 0 0 1
                  anchor -0.02 0.05 0
                }
                endPoint Solid {
                  translation -0.02 0.05 0
                  rotation 0 0 -1 2.131294828259337
                  children [
                    DEF r5 Pose {
                      children [
                        USE SMALL_WHEEL_SHAPE
                      ]
                    }
                  ]
                  name "sr5"
                  boundingObject USE r5
                  physics Physics {
                    density -1
                    mass 0.1
                  }
                  linearVelocity -0.19486346036913135 -0.7879601586464405 0.17342848903917313
                  angularVelocity 7.220244910358788 -3.080163726548008 -1.3914633195623272
                }
              }
              DEF sr6 HingeJoint {
                jointParameters HingeJointParameters {
                  position 105.30647323584202
                  axis 0 0 1
                  anchor -0.02 -0.05 0
                }
                endPoint Solid {
                  translation -0.02 -0.05 0
                  rotation 0 0 1 4.775508320968637
                  children [
                    DEF r6 Pose {
                      children [
                        USE SMALL_WHEEL_SHAPE
                      ]
                    }
                  ]
                  name "sr6"
                  boundingObject USE r6
                  physics Physics {
                    density -1
                    mass 0.1
                  }
                  linearVelocity -0.09293996507087082 -0.11589251731925071 -0.23009192858897015
                  angularVelocity 10.134643036327843 6.891058129952876 -7.659447533950033
                }
              }
              DEF sr7 HingeJoint {
                jointParameters HingeJointParameters {
                  position -53.700364459312624
                  axis 0 0.707107 0.707107
                  anchor -0.02 0.03535 -0.03535
                }
                endPoint Solid {
                  translation -0.02 0.03535 -0.03535
                  rotation 0 -0.7071067811865476 -0.7071067811865476 3.4348820018759323
                  children [
                    DEF r7 Pose {
                      rotation -1 0 0 0.76
                      children [
                        USE SMALL_WHEEL_SHAPE
                      ]
                    }
                  ]
                  name "sr7"
                  boundingObject USE r7
                  physics Physics {
                    density -1
                    mass 0.1
                  }
                  linearVelocity -0.2771527065770375 -0.8105437492669295 -0.12384128819945896
                  angularVelocity 6.871874607832464 -4.3245527121616 -2.4319717761846045
                }
              }
              DEF sr8 HingeJoint {
                jointParameters HingeJointParameters {
                  position -26.734833564942242
                  axis 0 0.707107 0.707107
                  anchor -0.02 -0.03535 0.03535
                }
                endPoint Solid {
                  translation -0.02 -0.03535 0.03535
                  rotation 0 -0.7071067811865476 -0.7071067811865476 1.6020923362238964
                  children [
                    DEF r8 Pose {
                      rotation -1 0 0 0.76
                      children [
                        USE SMALL_WHEEL_SHAPE
                      ]
                    }
                  ]
                  name "sr8"
                  boundingObject USE r8
                  physics Physics {
                    density -1
                    mass 0.1
                  }
                  linearVelocity -0.010693995225950858 -0.09347235812102993 0.06705831602813928
                  angularVelocity 7.520654729192726 -2.004431574852378 -1.8052812996954952
                }
              }
              DEF WHEEL_TRANS Pose {
                translation -0.02 0 0
                rotation 0 -1 0 1.5708
                children [
                  DEF WHEEL_SHAPE Shape {
                    appearance PBRAppearance {
                      baseColor 0.678431 0.847059 0.901961
                      roughness 1
                      metalness 0
                    }
                    geometry Cylinder {
                      height 0.02
                      radius 0.05
                      subdivision 20
                    }
                  }
                ]
              }
            ]
            boundingObject Pose {
              translation -0.02 0 0
              rotation 0 -1 0 1.5708
              children [
                DEF wheel1 Shape {
                  appearance PBRAppearance {
                    baseColor 0.8 0.8 0.8
                    transparency 0.12999999523162842
                    roughness 1
                    metalness 0
                    emissiveColor 0 1 0
                  }
                  geometry Cylinder {
                    height 0.02
                    radius 0.05
                  }
                }
              ]
            }
            physics Physics {
            }
            linearVelocity -0.14390199559296668 -0.45192611446986297 -0.028335014565483114
            angularVelocity 7.444500157966368 -2.2756232069462534 -1.8703420209446524
          }
        }
      ]
      name "wheel 1"
      boundingObject DEF DUMMY Sphere {
        radius 0.01
      }
      physics Physics {
      }
    }
    DEF SOLID2 Solid {
      rotation 0 0 1 1.5708
      children [
        DEF WHEEL2 HingeJoint {
          jointParameters HingeJointParameters {
            position 88.40804499945257
            axis -1 0 0
            anchor -0.1 0 0
          }
          device [
            RotationalMotor {
              name "wheel2"
            }
          ]
          endPoint Solid {
            translation -0.2399999999999999 8.667398876564157e-06 1.6497731810298495e-05
            rotation -0.9999999999996402 8.207507272466075e-07 -2.149503085899122e-07 0.44585631833409994
            children [
              DEF sr1 HingeJoint {
                jointParameters HingeJointParameters {
                  position 36.06252528295745
                  axis 0 1 0
                  anchor -0.02 0 0.05
                }
                endPoint Solid {
                  translation -0.02 0 0.05
                  rotation 0 -1 0 1.6365865601200666
                  children [
                    USE r1
                  ]
                  name "sr1"
                  boundingObject USE r1
                  physics Physics {
                    density -1
                    mass 0.1
                  }
                  linearVelocity 0.7950829146915287 -0.2447228983192604 -0.28476531400614474
                  angularVelocity 2.4568614513373728 7.449653954117081 -2.1459284927243782
                }
              }
              DEF sr2 HingeJoint {
                jointParameters HingeJointParameters {
                  position -17.004564571015585
                  axis 0 -0.707107 0.707107
                  anchor -0.02 0.03535 0.03535
                }
                endPoint Solid {
                  translation -0.02 0.03535 0.03535
                  rotation 0 0.7071067811865475 -0.7071067811865475 4.438193956656412
                  children [
                    USE r2
                  ]
                  name "sr2"
                  boundingObject USE r2
                  physics Physics {
                    density -1
                    mass 0.1
                  }
                  linearVelocity 0.5694989758832263 -0.24028438201377567 -0.4948081249810387
                  angularVelocity 1.901231696767047 7.607893311926542 -1.8454839123506173
                }
              }
              DEF sr3 HingeJoint {
                jointParameters HingeJointParameters {
                  position 42.235911333348
                  axis 0 1 0
                  anchor -0.02 0 -0.05
                }
                endPoint Solid {
                  translation -0.02 0 -0.05
                  rotation 0 1 0 4.5367994902704805
                  children [
                    USE r3
                  ]
                  name "sr3"
                  boundingObject USE r3
                  physics Physics {
                    density -1
                    mass 0.1
                  }
                  linearVelocity 0.11097611447922866 0.006942990480614666 0.03148771329334819
                  angularVelocity -0.11510090021324115 8.169967791342918 -1.0269224761327496
                }
              }
              DEF sr4 HingeJoint {
                jointParameters HingeJointParameters {
                  position 115.31582391015773
                  axis 0 -0.707107 0.707107
                  anchor -0.02 -0.03535 -0.03535
                }
                endPoint Solid {
                  translation -0.02 -0.03535 -0.03535
                  rotation 0 -0.7071067811865475 0.7071067811865475 2.2184883809251756
                  children [
                    USE r4
                  ]
                  name "sr4"
                  boundingObject USE r4
                  physics Physics {
                    density -1
                    mass 0.1
                  }
                  linearVelocity 0.3367201205522671 0.0024625014634580425 0.24150215140363823
                  angularVelocity 0.8710093971390225 7.9230706293925275 0.902157091456282
                }
              }
              DEF sr5 HingeJoint {
                jointParameters HingeJointParameters {
                  position -52.44343702614695
                  axis 0 0 1
                  anchor -0.02 0.05 0
                }
                endPoint Solid {
                  translation -0.02 0.05 0
                  rotation 0 0 -1 2.177954568710261
                  children [
                    USE r5
                  ]
                  name "sr5"
                  boundingObject USE r5
                  physics Physics {
                    density -1
                    mass 0.1
                  }
                  linearVelocity 0.27576004243577423 -0.16477298349104227 -0.4892647732929264
                  angularVelocity -4.973819376849302 9.748945553676416 -18.894178413059677
                }
              }
              DEF sr6 HingeJoint {
                jointParameters HingeJointParameters {
                  position 40.359773710670034
                  axis 0 0 1
                  anchor -0.02 -0.05 0
                }
                endPoint Solid {
                  translation -0.02 -0.05 0
                  rotation 0 0 1 2.660661867592515
                  children [
                    USE r6
                  ]
                  name "sr6"
                  boundingObject USE r6
                  physics Physics {
                    density -1
                    mass 0.1
                  }
                  linearVelocity 0.6304571231561058 -0.07304930033123068 0.23597310957676043
                  angularVelocity 3.2615925742319054 7.259240757939178 1.2537571189097068
                }
              }
              DEF sr7 HingeJoint {
                jointParameters HingeJointParameters {
                  position 290.140146878069
                  axis 0 0.707107 0.707107
                  anchor -0.02 0.03535 -0.03535
                }
                endPoint Solid {
                  translation -0.02 0.03535 -0.03535
                  rotation 0 0.7071067811865476 0.7071067811865476 1.1136227478080258
                  children [
                    USE r7
                  ]
                  name "sr7"
                  boundingObject USE r7
                  physics Physics {
                    density -1
                    mass 0.1
                  }
                  linearVelocity 0.08594741254466343 -0.06238653680161121 -0.27122639666673753
                  angularVelocity 2.7765412531688907 7.3648037381493685 -1.556435530569432
                }
              }
              DEF sr8 HingeJoint {
                jointParameters HingeJointParameters {
                  position 32.22427084698575
                  axis 0 0.707107 0.707107
                  anchor -0.02 -0.03535 0.03535
                }
                endPoint Solid {
                  translation -0.02 -0.03535 0.03535
                  rotation 0 -0.7071067811865475 -0.7071067811865475 5.474840996091766
                  children [
                    USE r8
                  ]
                  name "sr8"
                  boundingObject USE r8
                  physics Physics {
                    density -1
                    mass 0.1
                  }
                  linearVelocity 0.8202699547757742 -0.17543571724657803 0.017935784037601557
                  angularVelocity 3.6631027362942223 7.121446972073807 -1.1976777165653325
                }
              }
              USE WHEEL_TRANS
            ]
            boundingObject Pose {
              translation -0.02 0 0
              rotation 0 -1 0 1.5708
              children [
                DEF wheel1 Shape {
                  appearance PBRAppearance {
                    baseColor 0.8 0.8 0.8
                    transparency 0.12999999523162842
                    roughness 1
                    metalness 0
                    emissiveColor 0 1 0
                  }
                  geometry Cylinder {
                    height 0.02
                    radius 0.05
                  }
                }
              ]
            }
            physics Physics {
            }
            linearVelocity 0.45310776614071624 -0.1189112770678538 -0.12664722341694906
            angularVelocity 1.926953794769491 7.601566538899715 -1.8902247085668533
          }
        }
      ]
      name "wheel 2"
      boundingObject USE DUMMY
      physics Physics {
      }
    }
    DEF SOLID3 Solid {
      rotation 0 0 1 3.14159
      children [
        DEF WHEEL3 HingeJoint {
          jointParameters HingeJointParameters {
            position 78.1722203073467
            axis -1 0 0
            anchor -0.1 0 0
          }
          device [
            RotationalMotor {
              name "wheel3"
            }
          ]
          endPoint Solid {
            translation -0.24000199999999997 -4.646360780916182e-06 -7.194828102162273e-06
            rotation 0.9999999998754714 1.4098586145878385e-05 7.091341199780812e-06 3.5052794078311416
            children [
              DEF sr1 HingeJoint {
                jointParameters HingeJointParameters {
                  position -73.70207673046112
                  axis 0 1 0
                  anchor -0.02 0 0.05
                }
                endPoint Solid {
                  translation -0.02 0 0.05
                  rotation 0 1 0 1.6961469556939222
                  children [
                    USE r1
                  ]
                  name "sr1"
                  boundingObject USE r1
                  physics Physics {
                    density -1
                    mass 0.1
                  }
                  linearVelocity 0.05877122125651991 0.09756019694824956 -0.271765334525568
                  angularVelocity -7.576163649581545 3.431438553016946 -1.3108888143866364
                }
              }
              DEF sr2 HingeJoint {
                jointParameters HingeJointParameters {
                  position -21.515472116368056
                  axis 0 -0.707107 0.707107
                  anchor -0.02 0.03535 0.03535
                }
                endPoint Solid {
                  translation -0.02 0.03535 0.03535
                  rotation 0 -0.7071067811865475 0.7071067811865475 3.6172691123502902
                  children [
                    USE r2
                  ]
                  name "sr2"
                  boundingObject USE r2
                  physics Physics {
                    density -1
                    mass 0.1
                  }
                  linearVelocity -0.011862646770214813 0.1161111145981777 0.045338330185907674
                  angularVelocity -8.686730820865614 -0.5878737749237885 -0.8478582124384045
                }
              }
              DEF sr3 HingeJoint {
                jointParameters HingeJointParameters {
                  position 45.708946384133746
                  axis 0 1 0
                  anchor -0.02 0 -0.05
                }
                endPoint Solid {
                  translation -0.02 0 -0.05
                  rotation 0 -1 0 4.556536073302945
                  children [
                    USE r3
                  ]
                  name "sr3"
                  boundingObject USE r3
                  physics Physics {
                    density -1
                    mass 0.1
                  }
                  linearVelocity 0.1812669995747569 0.8583244682103837 0.0487986604711735
                  angularVelocity -7.445142624767893 3.909973286756117 -1.104703218416506
                }
              }
              DEF sr4 HingeJoint {
                jointParameters HingeJointParameters {
                  position 2.2633532393602223
                  axis 0 -0.707107 0.707107
                  anchor -0.02 -0.03535 -0.03535
                }
                endPoint Solid {
                  translation -0.02 -0.03535 -0.03535
                  rotation 0 -0.7071067811865475 0.7071067811865475 2.2633532393602223
                  children [
                    USE r4
                  ]
                  name "sr4"
                  boundingObject USE r4
                  physics Physics {
                    density -1
                    mass 0.1
                  }
                  linearVelocity 0.25192334636425007 0.8398674853720135 -0.26842674824104495
                  angularVelocity -7.678162146639387 3.044228786827433 -2.307539400333913
                }
              }
              DEF sr5 HingeJoint {
                jointParameters HingeJointParameters {
                  position -13.624455272649397
                  axis 0 0 1
                  anchor -0.02 0.05 0
                }
                endPoint Solid {
                  translation -0.02 0.05 0
                  rotation 0 0 -1 1.0580846582902248
                  children [
                    USE r5
                  ]
                  name "sr5"
                  boundingObject USE r5
                  physics Physics {
                    density -1
                    mass 0.1
                  }
                  linearVelocity -0.0053022117444551774 0.34640739066407317 0.2707698175190444
                  angularVelocity -8.337493134917967 0.7960948009349389 1.3150778691449327
                }
              }
              DEF sr6 HingeJoint {
                jointParameters HingeJointParameters {
                  position -3.2219184313915616
                  axis 0 0 1
                  anchor -0.02 -0.05 0
                }
                endPoint Solid {
                  translation -0.02 -0.05 0
                  rotation 0 0 -0.9999999999999999 3.2219184313915616
                  children [
                    USE r6
                  ]
                  name "sr6"
                  boundingObject USE r6
                  physics Physics {
                    density -1
                    mass 0.1
                  }
                  linearVelocity 0.2453401539590821 0.6094769625929052 -0.49375039394676606
                  angularVelocity -7.973894643229846 1.999320574844529 -1.6911660766709626
                }
              }
              DEF sr7 HingeJoint {
                jointParameters HingeJointParameters {
                  position 67.42963492101684
                  axis 0 0.707107 0.707107
                  anchor -0.02 0.03535 -0.03535
                }
                endPoint Solid {
                  translation -0.02 0.03535 -0.03535
                  rotation 0 0.7071067811865476 0.7071067811865476 4.5977818492209765
                  children [
                    USE r7
                  ]
                  name "sr7"
                  boundingObject USE r7
                  physics Physics {
                    density -1
                    mass 0.1
                  }
                  linearVelocity 0.07471934494717952 0.6538777949158137 0.2720979775610432
                  angularVelocity -7.581646540633487 3.519884422101063 1.7133007649355811
                }
              }
              DEF sr8 HingeJoint {
                jointParameters HingeJointParameters {
                  position -77.64984547687439
                  axis 0 0.707107 0.707107
                  anchor -0.02 -0.03535 0.03535
                }
                endPoint Solid {
                  translation -0.02 -0.03535 0.03535
                  rotation 0 -0.7071067811865476 -0.7071067811865476 2.251621790719352
                  children [
                    USE r8
                  ]
                  name "sr8"
                  boundingObject USE r8
                  physics Physics {
                    density -1
                    mass 0.1
                  }
                  linearVelocity 0.16531883021998348 0.30200714634487297 -0.49506553079887244
                  angularVelocity -10.219689919970223 -5.0695191711580545 -20.731128663378424
                }
              }
              USE WHEEL_TRANS
            ]
            boundingObject Pose {
              translation -0.02 0 0
              rotation 0 -1 0 1.5708
              children [
                DEF wheel1 Shape {
                  appearance PBRAppearance {
                    baseColor 0.8 0.8 0.8
                    transparency 0.12999999523162842
                    roughness 1
                    metalness 0
                    emissiveColor 0 1 0
                  }
                  geometry Cylinder {
                    height 0.02
                    radius 0.05
                  }
                }
              ]
            }
            physics Physics {
            }
            linearVelocity 0.12001855483168561 0.47794152956852876 -0.11148589161028058
            angularVelocity -7.950398015467914 2.0842479746706624 -1.879710034041304
          }
        }
      ]
      name "wheel 3"
      boundingObject USE DUMMY
      physics Physics {
      }
    }
    DEF SOLID4 Solid {
      rotation 0 0 1 4.71239
      children [
        DEF WHEEL4 HingeJoint {
          jointParameters HingeJointParameters {
            position 75.62778070615363
            axis -1 0 0
            anchor -0.1 0 0
          }
          device [
            RotationalMotor {
              name "wheel4"
            }
          ]
          endPoint Solid {
            translation -0.24000000000000013 3.112863739718352e-06 1.9767967783875695e-05
            rotation -0.9999999999984251 1.7737606643717622e-06 -5.8136776577457844e-08 0.2295571775568985
            children [
              DEF sr1 HingeJoint {
                jointParameters HingeJointParameters {
                  position 8.504222472455302
                  axis 0 1 0
                  anchor -0.02 0 0.05
                }
                endPoint Solid {
                  translation -0.02 0 0.05
                  rotation 0 -1 0 4.062148141903871
                  children [
                    USE r1
                  ]
                  name "sr1"
                  boundingObject USE r1
                  physics Physics {
                    density -1
                    mass 0.1
                  }
                  linearVelocity -0.8579041369570453 0.28275080209906317 -0.09307910793639458
                  angularVelocity -2.9923089011427386 -7.633226685763509 -2.001014806807656
                }
              }
              DEF sr2 HingeJoint {
                jointParameters HingeJointParameters {
                  position -25.37532756456685
                  axis 0 -0.707107 0.707107
                  anchor -0.02 0.03535 0.03535
                }
                endPoint Solid {
                  translation -0.02 0.03535 0.03535
                  rotation 0 0.7071067811865476 -0.7071067811865476 0.24258633584850306
                  children [
                    USE r2
                  ]
                  name "sr2"
                  boundingObject USE r2
                  physics Physics {
                    density -1
                    mass 0.1
                  }
                  linearVelocity -0.6745204197121415 0.28898938864188806 -0.3551769070900753
                  angularVelocity -1.8172916006609945 -7.9666205462155535 -0.9282320433187359
                }
              }
              DEF sr3 HingeJoint {
                jointParameters HingeJointParameters {
                  position 156.26994076384187
                  axis 0 1 0
                  anchor -0.02 0 -0.05
                }
                endPoint Solid {
                  translation -0.02 0 -0.05
                  rotation 0 1 0 5.4734933915317985
                  children [
                    USE r3
                  ]
                  name "sr3"
                  boundingObject USE r3
                  physics Physics {
                    density -1
                    mass 0.1
                  }
                  linearVelocity -0.09552598964927161 0.007311690232493722 0.06637951960645994
                  angularVelocity -1.8576711593857342 -7.949881146961394 -1.7822945953569223
                }
              }
              DEF sr4 HingeJoint {
                jointParameters HingeJointParameters {
                  position 27.088318463816595
                  axis 0 -0.707107 0.707107
                  anchor -0.02 -0.03535 -0.03535
                }
                endPoint Solid {
                  translation -0.02 -0.03535 -0.03535
                  rotation 0 -0.7071067811865475 0.7071067811865475 1.955577235098249
                  children [
                    USE r4
                  ]
                  name "sr4"
                  boundingObject USE r4
                  physics Physics {
                    density -1
                    mass 0.1
                  }
                  linearVelocity -0.2790501444151019 0.0011075943834319155 0.32848159246323855
                  angularVelocity -1.776622475391414 -7.977269131619365 -0.8730606436500158
                }
              }
              DEF sr5 HingeJoint {
                jointParameters HingeJointParameters {
                  position -29.276095159170197
                  axis 0 0 1
                  anchor -0.02 0.05 0
                }
                endPoint Solid {
                  translation -0.02 0.05 0
                  rotation 0 0 -1 4.143353930451851
                  children [
                    USE r5
                  ]
                  name "sr5"
                  boundingObject USE r5
                  physics Physics {
                    density -1
                    mass 0.1
                  }
                  linearVelocity -0.37534802400566897 0.21094050419856544 -0.41709704716220053
                  angularVelocity -4.037672650388824 -7.441651051933539 6.468105447101108
                }
              }
              DEF sr6 HingeJoint {
                jointParameters HingeJointParameters {
                  position 7.050129809604436
                  axis 0 0 1
                  anchor -0.02 -0.05 0
                }
                endPoint Solid {
                  translation -0.02 -0.05 0
                  rotation 0 0 -1 5.516240804754737
                  children [
                    USE r6
                  ]
                  name "sr6"
                  boundingObject USE r6
                  physics Physics {
                    density -1
                    mass 0.1
                  }
                  linearVelocity -0.578220604755211 0.07915796194336261 0.39043993775232977
                  angularVelocity -2.9341436792910436 -7.665893579988385 0.7208240163492128
                }
              }
              DEF sr7 HingeJoint {
                jointParameters HingeJointParameters {
                  position -98.86259938109364
                  axis 0 0.707107 0.707107
                  anchor -0.02 0.03535 -0.03535
                }
                endPoint Solid {
                  translation -0.02 0.03535 -0.03535
                  rotation 0 0.7071067811865476 0.7071067811865476 1.6683655337797387
                  children [
                    USE r7
                  ]
                  name "sr7"
                  boundingObject USE r7
                  physics Physics {
                    density -1
                    mass 0.1
                  }
                  linearVelocity -0.135617510623208 0.09427930943755086 -0.24240829505843253
                  angularVelocity -4.1066291755213715 -7.330592712059711 -0.724043215942225
                }
              }
              DEF sr8 HingeJoint {
                jointParameters HingeJointParameters {
                  position 13.370457533166975
                  axis 0 0.707107 0.707107
                  anchor -0.02 -0.03535 0.03535
                }
                endPoint Solid {
                  translation -0.02 -0.03535 0.03535
                  rotation 0 0.7071067811865475 0.7071067811865475 0.8040869188078025
                  children [
                    USE r8
                  ]
                  name "sr8"
                  boundingObject USE r8
                  physics Physics {
                    density -1
                    mass 0.1
                  }
                  linearVelocity -0.8179518640433612 0.19581906775685537 0.21575293147329638
                  angularVelocity -2.5850504236898355 -7.7493565758692196 -1.774846621257613
                }
              }
              USE WHEEL_TRANS
            ]
            boundingObject Pose {
              translation -0.02 0 0
              rotation 0 -1 0 1.5708
              children [
                DEF wheel1 Shape {
                  appearance PBRAppearance {
                    baseColor 0.8 0.8 0.8
                    transparency 0.12999999523162842
                    roughness 1
                    metalness 0
                    emissiveColor 0 1 0
                  }
                  geometry Cylinder {
                    height 0.02
                    radius 0.05
                  }
                }
              ]
            }
            physics Physics {
            }
            linearVelocity -0.47678457884300923 0.14504877777031844 -0.013331582647246584
            angularVelocity -2.432900391527927 -7.793347782570815 -1.8597535905975138
          }
        }
      ]
      name "wheel 4"
      boundingObject USE DUMMY
      physics Physics {
      }
    }
    DEF BODY_TRANS Pose {
      translation 0 0 0.1
      children [
        Shape {
          appearance PBRAppearance {
            baseColor 0.564706 0.933333 0.564706
            roughness 1
            metalness 0
          }
          geometry Cylinder {
            height 0.002
            radius 0.26
            subdivision 8
          }
        }
      ]
    }
  ]
  boundingObject USE BODY_TRANS
  physics Physics {
    density -1
    mass 8.5
  }
  controller "roda_empat_test"
  linearVelocity -0.021076434765140553 0.03824643775599737 -0.06998695435859226
  angularVelocity -0.2530028834074104 -0.09585546494219607 -1.8576229583401278
}
